Workbook

Sheet Tgl 9
A1: REKAPAN PENGAJUAN | J1: REKAPAN PENGAJUAN
A2: PER TANGGAL 9 Januari 2026 | J2: PER TANGGAL 9 Januari 2026
A3: POSISI KAS SAAT INI | J3: POSISI KAS SAAT INI
C4: Kas Besar (Nisa) | D4: 0 | L4: Kas Besar (Nisa) | M4: 0
C5: Mandiri Akhmad Jaelani | D5: 91703579 | L5: Mandiri Akhmad Jaelani | M5: 91703579
C6: Mandiri CBS | D6: 256369459 | L6: Mandiri CBS | M6: 256369459
C7: BJB CBS | D7: 1061000 | L7: BJB CBS | M7: 1061000
C8: BJB CRS | D8: =22890124-21500000 -> 1390124 | L8: BJB CRS | M8: =22890124-21500000 -> 1390124
C9: BRI CRS | D9: 740468.8 | L9: BRI CRS | M9: 740468.8
A11: TOTAL POSISI KAS DAN BANK TGL 9 Januari 2026 | H11: =SUM(D4:D9) -> 3.5126463e+08 | J11: TOTAL POSISI KAS DAN BANK TGL 9 Januari 2026 | Q11: =SUM(M4:M9) -> 3.5126463e+08
A12: UMUM | J12: UMUM
A13: TGL | B13: NO KAS | C13: KETERANGAN PENGAJUAN | D13: PENGAJUAN | E13: PENCAIRAN | J13: TGL | K13: NO KAS | L13: KETERANGAN PENGAJUAN | M13: PENGAJUAN | N13: PENCAIRAN
E14: SUDAH | F14: CASH | G14: GIRO | H14: TRANSFER | N14: SUDAH | O14: CASH | P14: GIRO | Q14: TRANSFER
B15: Ku.25.261 | C15: Listrik | D15: 503500 | K15: Ku.25.261 | L15: Listrik | M15: 503500
B16: Ku.25.261 | C16: Telphone & Internet | D16: 503500 | K16: Ku.25.261 | L16: Telphone & Internet | M16: 503500
B17: Ku.25.001 | C17: Air Minum (1 Gln) | D17: 16000 | K17: Ku.25.001 | L17: Air Minum (1 Gln) | M17: 16000
C28: JUMLAH PENGAJUAN UMUM | D28: =SUM(D15:D27) -> 1023000 | L28: JUMLAH PENGAJUAN UMUM | M28: =SUM(M15:M27) -> 1023000
C29: Jumlah Yang Belum Dibayar | H29: =+D28 -> 1023000 | L29: Jumlah Yang Belum Dibayar | Q29: =+M28 -> 1023000
A30: TOTAL PENGAJUAN UMUM | E30: =+H29 -> 1023000 | J30: TOTAL PENGAJUAN UMUM | N30: =+Q29 -> 1023000
A31: ALCENT | J31: ALCENT
B32: Kt.26.018 | C32: Upah Tukang Pekerjaan Pengecetan Ruang Kls (Pa Mamat) Pro TK | D32: 390000 | K32: Kt.26.018 | L32: Upah Tukang Pekerjaan Pengecetan Ruang Kls (Pa Mamat) Pro TK | M32: 390000
B33: Kt.26.018 | C33: Upah Tukang Listrik Pek Pengecekan R.TU (Pa Soni) Pro TK | D33: 100000 | K33: Kt.26.018 | L33: Upah Tukang Listrik Pek Pengecekan R.TU (Pa Soni) Pro TK | M33: 100000
B34: Kt.26.017 | C34: Upah Tukang Pek Talang Air Area Aula,Pemasangan Rambang,dll (Pa Mamat) Pro SMP | D34: 1940000 | K34: Kt.26.017 | L34: Upah Tukang Pek Talang Air Area Aula,Pemasangan Rambang,dll (Pa Mamat) Pro SMP | M34: 1940000
B35: Kt.26.017 | C35: Upah Pa Dedi (1 Hari) Pro SMP | D35: 150000 | K35: Kt.26.017 | L35: Upah Pa Dedi (1 Hari) Pro SMP | M35: 150000
B36: Kt.26.017 | C36: Upah Pa Heri Pro SMP | D36: 440000 | K36: Kt.26.017 | L36: Upah Pa Heri Pro SMP | M36: 440000
B37: Kt.26.016 | C37: Upah Tukang Pek Dren Ac Ruang Kls 201,Cet Plapon Bekas,dll(Pa Mamat) Pro SMA | D37: 1880000 | K37: Kt.26.016 | L37: Upah Tukang Pek Dren Ac Ruang Kls 201,Cet Plapon Bekas,dll(Pa Mamat) Pro SMA | M37: 1880000
B38: Kt.26.016 | C38: Upah Tukang Listrik Pek perbaikan Konslet STK R.209,210 (Pa Soni) Pro SMA | D38: 114000 | K38: Kt.26.016 | L38: Upah Tukang Listrik Pek perbaikan Konslet STK R.209,210 (Pa Soni) Pro SMA | M38: 114000
B39: Kt.26.016 | C39: Upah Pa Dedi (5 Hari) Pro SMA | D39: =150000*5 -> 750000 | K39: Kt.26.016 | L39: Upah Pa Dedi (5 Hari) Pro SMA | M39: =150000*5 -> 750000
B40: Kt.26.016 | C40: Upah Heri Pro SMA | D40: 440000 | K40: Kt.26.016 | L40: Upah Heri Pro SMA | M40: 440000
B41: Kt.26.016 | C41: Bon Talangan Pa Mamat (Pemb Semen & Lem Fiber) Pro SMA | D41: 40000 | K41: Kt.26.016 | L41: Bon Talangan Pa Mamat (Pemb Semen & Lem Fiber) Pro SMA | M41: 40000
B42: Kt.26.020 | C42: Pelunasan Pek Plang No Smoking (Pa Yoda) Pro SMA | D42: 900000 | K42: Kt.26.020 | L42: Pelunasan Pek Plang No Smoking (Pa Yoda) Pro SMA | M42: 900000
B43: Kt.26.025 | C43: Pek Perbaikan Pintu HPL (Pa Yoda) Pro SMA | D43: 2000000 | K43: Kt.26.025 | L43: Pek Perbaikan Pintu HPL (Pa Yoda) Pro SMA | M43: 2000000
B44: Kt.26.023 | C44: Pemb Matrial Alcent (Pa Mamat) | D44: 700000 | K44: Kt.26.023 | L44: Pemb Matrial Alcent (Pa Mamat) | M44: 700000
C46: JUMLAH PENGAJUAN SD,SMP,SMA | D46: =SUM(D32:D44) -> 9844000 | L46: JUMLAH PENGAJUAN SD,SMP,SMA | M46: =SUM(M32:M44) -> 9844000
C47: Jumlah Yang Belum Dibayar | E47: =D46 -> 9844000 | L47: Jumlah Yang Belum Dibayar | N47: =M46 -> 9844000
A48: Jl. Gitar & Antapani | J48: Jl. Gitar & Antapani
B49: Kt.26.019 | C49: Upah Pa Yoda Perbaikan Pintu Pro Jl Gitar | D49: 760000 | K49: Kt.26.019 | L49: Upah Pa Yoda Perbaikan Pintu Pro Jl Gitar | M49: 760000
B50: Kt.26.024 | C50: Pemb Pompa Dorong Antapani | D50: 700000 | K50: Kt.26.024 | L50: Pemb Pompa Dorong Antapani | M50: 700000
C51: JUMLAH PENGAJUAN Jl. Gitar | D51: =SUM(D49:D50) -> 1460000 | E51: 0 | F51: 0 | L51: JUMLAH PENGAJUAN Jl. Gitar | M51: =SUM(M49:M50) -> 1460000 | N51: 0 | O51: 0
C52: Jumlah Yang Belum Dibayar | E52: =D51 -> 1460000 | L52: Jumlah Yang Belum Dibayar | N52: =M51 -> 1460000
...

Sheet Sheet2
A1: PA HERI | C1: Pa Dedi | E1: PA MAMAT | G1: NISA | I1: Pa Uden | K1: Pa Engkus
A2: Upah Pa Heri Pro SMP | B2: 440000 | C2: Upah Pa Dedi (1 Hari) Pro SMP | D2: 150000 | E2: Upah Tukang Pekerjaan Pengecetan Ruang Kls (Pa Mamat) Pro TK | F2: 390000 | G2: Listrik | H2: 503500
A3: Upah Heri Pro SMA | B3: 440000 | C3: Upah Pa Dedi (5 Hari) Pro SMA | D3: 750000 | E3: Upah Tukang Pek Talang Air Area Aula,Pemasangan Rambang,dll (Pa Mamat) Pro SMP | F3: 1940000 | G3: Telphone & Internet | H3: 503500
A4: Upah Pa Heri (Sumedang) | B4: 220000 | C4: Upah Pa Dedi (Sumedang) | D4: 150000 | E4: Upah Tukang Pek Dren Ac Ruang Kls 201,Cet Plapon Bekas,dll(Pa Mamat) Pro SMA | F4: 1880000 | G4: Air Minum (1 Gln) | H4: 16000
A5: Upah Pa Heri (Pembuatan RAB) RT Bu Ani | B5: 220000 | E5: Bon Talangan Pa Mamat (Pemb Semen & Lem Fiber) Pro SMA | F5: 40000 | G5: Upah Tukang Listrik Pek Pengecekan R.TU (Pa Soni) Pro TK | H5: 100000
A6: Upah Pa Yoda Perbaikan Pintu Pro Jl Gitar | B6: 760000 | G6: Upah Tukang Listrik Pek perbaikan Konslet STK R.209,210 (Pa Soni) Pro SMA | H6: 114000
A7: Pemb Pompa Dorong Antapani | B7: 700000 | G7: KONTRABON RESTULOGAM 27/12 SMA | H7: 2372500
G8: KONTRABON RESTULOGAM 27/12 Bd Indah | H8: 250000
G9: KONTRABON RESTULOGAM 29/12 TK | H9: 1035500
G10: Pek Neon Sign (Pa Karsana) Antapani | H10: 1750000
G11: Pelunasan Pek Plang No Smoking (Pa Yoda) Pro SMA | H11: 900000
G12: Pek Perbaikan Pintu HPL (Pa Yoda) Pro SMA | H12: 2000000
G13: Pemb Matrial Alcent (Pa Mamat) | H13: 700000
B15: =SUM(B2:B14) -> 2780000 | D15: =SUM(D2:D14) -> 1050000 | F15: =SUM(F2:F14) -> 4250000 | H15: =SUM(H2:H14) -> 10245000 | J15: =SUM(J2:J14) -> 0 | K15: =SUM(K2:K14) -> 0 | L15: =SUM(L2:L14) -> 0
C16: Kasbon | D16: 100000
C17: =B2+B3+B4+B5 -> 1320000 | D17: =D15-D16 -> 950000
A20: Pencairan | B20: =B15+D15+F15+H15+J15 -> 18325000
A21: Cash | B21: ='Tgl 9'!M102 -> 18000000
A23: Kekurangan | B23: =B20-B21 -> 325000

Sheet Tgl 10
A1: REKAPAN PENGAJUAN | J1: REKAPAN PENGAJUAN
A2: PER TANGGAL 14 Januari 2026 | J2: PER TANGGAL 14 Januari 2026
A3: POSISI KAS SAAT INI | J3: POSISI KAS SAAT INI
C4: Kas Besar (Nisa) | D4: 0 | L4: Kas Besar (Nisa) | M4: 0
C5: Mandiri Akhmad Jaelani | D5: 118418079 | L5: Mandiri Akhmad Jaelani | M5: 118418079
C6: Mandiri CBS | D6: 306369459 | L6: Mandiri CBS | M6: 306369459
C7: BJB CBS | D7: 1146153 | L7: BJB CBS | M7: 1146153
C8: BJB CRS | D8: 3297736 | L8: BJB CRS | M8: 3297736
C9: BRI CRS | D9: 2626657 | L9: BRI CRS | M9: 2626657
A11: TOTAL POSISI KAS DAN BANK TGL 14 Januari 2026 | H11: =SUM(D4:D9) -> 431858084 | J11: TOTAL POSISI KAS DAN BANK TGL 14 Januari 2026 | Q11: =SUM(M4:M9) -> 431858084
A12: UMUM | J12: UMUM
A13: TGL | B13: NO KAS | C13: KETERANGAN PENGAJUAN | D13: PENGAJUAN | E13: PENCAIRAN | J13: TGL | K13: NO KAS | L13: KETERANGAN PENGAJUAN | M13: PENGAJUAN | N13: PENCAIRAN
E14: SUDAH | F14: CASH | G14: GIRO | H14: TRANSFER | N14: SUDAH | O14: CASH | P14: GIRO | Q14: TRANSFER
B15: Ku.26.006 | C15: Kerohiman (Pa Ocid) | D15: 500000 | K15: Ku.26.006 | L15: Kerohiman (Pa Ocid) | M15: 500000
B16: Ku.26.006 | C16: Pemb Tinta HP Smart 7740 (4 Btl) | D16: 2000000 | K16: Ku.26.006 | L16: Pemb Tinta HP Smart 7740 (4 Btl) | M16: 2000000
B17: Ku.26.006 | C17: Upah Pa Dedi Ke Jakarta | D17: =150000+20000*6 -> 270000 | K17: Ku.26.006 | L17: Upah Pa Dedi Ke Jakarta | M17: =150000+20000*6 -> 270000
B18: Ku.26.006 | C18: Buku Pengajuan | D18: 300000 | K18: Ku.26.006 | L18: Buku Pengajuan | M18: 300000
C28: JUMLAH PENGAJUAN UMUM | D28: =SUM(D15:D27) -> 3070000 | L28: JUMLAH PENGAJUAN UMUM | M28: =SUM(M15:M27) -> 3070000
B29: Jumlah Yang Belum Dibayar | H29: =+D28 -> 3070000 | K29: Jumlah Yang Belum Dibayar | Q29: =+M28 -> 3070000
A30: TOTAL PENGAJUAN UMUM | E30: =+H29 -> 3070000 | J30: TOTAL PENGAJUAN UMUM | N30: =+Q29 -> 3070000
A31: ALCENT | J31: ALCENT
B32: Kt.26.005 | C32: Pelunasan Pek Gordeng Pro SD | D32: 4068000 | K32: Kt.26.005 | L32: Pelunasan Pek Gordeng Pro SD | M32: 4068000
B33: Kt.26.230 | C33: Konsumsi Rapat 12/1 Pro SD | D33: 311500 | K33: Kt.26.230 | L33: Konsumsi Rapat 12/1 Pro SD | M33: 311500
B34: Kt.26.040 | C34: Upah Tukang (Pa mamat) Pek Pasang Karpet,Aksesoris,dll Pro SMP | D34: 110000 | K34: Kt.26.040 | L34: Upah Tukang (Pa mamat) Pek Pasang Karpet,Aksesoris,dll Pro SMP | M34: 1110000
B35: Kt.26.040 | C35: Upah Pa Heri Pro SMP | D35: 220000 | K35: Kt.26.040 | L35: Upah Pa Heri Pro SMP | M35: 220000
B36: Kt.26.041 | C36: Upah Tukang Pa Mamat (Pek Dren AC 201 LT 2 )Pro SMA | D36: 2480000 | K36: Kt.26.041 | L36: Upah Tukang Pa Mamat (Pek Dren AC 201 LT 2 )Pro SMA | M36: 2480000
B37: Kt.26.041 | C37: Upah Pa Dedi (5 Hari) Pro SMA | D37: =150000*2 -> 300000 | K37: Kt.26.041 | L37: Upah Pa Dedi (5 Hari) Pro SMA | M37: =150000*2 -> 300000
C39: JUMLAH PENGAJUAN SD,SMP,SMA | D39: =SUM(D32:D38) -> 7489500 | L39: JUMLAH PENGAJUAN SD,SMP,SMA | M39: =SUM(M32:M38) -> 8489500
C40: Jumlah Yang Belum Dibayar | E40: =D39 -> 7489500 | L40: Jumlah Yang Belum Dibayar | N40: =M39 -> 8489500
A41: Jl. Gitar & Antapani | J41: Jl. Gitar & Antapani
B42: Kt.26.019 | C42: Upah Pa Yoda Perbaikan Pintu Pro Jl Gitar | K42: Kt.26.019 | L42: Upah Pa Yoda Perbaikan Pintu Pro Jl Gitar
B43: Kt.26.024 | C43: Pemb Pompa Dorong Antapani | K43: Kt.26.024 | L43: Pemb Pompa Dorong Antapani
C44: JUMLAH PENGAJUAN Jl. Gitar | D44: =SUM(D42:D43) -> 0 | E44: 0 | F44: 0 | L44: JUMLAH PENGAJUAN Jl. Gitar | M44: =SUM(M42:M43) -> 0 | N44: 0 | O44: 0
C45: Jumlah Yang Belum Dibayar | E45: =D44 -> 0 | L45: Jumlah Yang Belum Dibayar | N45: =M44 -> 0
A46: Sumedang | J46: Sumedang
B47: Kt.26.042 | C47: Upah Pa Heri (Sumedang) | D47: =220000*3 -> 660000 | K47: Kt.26.042 | L47: Upah Pa Heri (Sumedang) | M47: =220000*3 -> 660000
C51: JUMLAH PENGAJUAN Sumedang | D51: =SUM(D47:D50) -> 660000 | E51: 0 | F51: 0 | L51: JUMLAH PENGAJUAN Sumedang | M51: =SUM(M47:M50) -> 660000 | N51: 0 | O51: 0
C52: Jumlah Yang Belum Dibayar | E52: =D51 -> 660000 | L52: Jumlah Yang Belum Dibayar | N52: =M51 -> 660000
A53: KONTRABON | J53: KONTRABON
B54: Kt.26.037 | C54: KONTRABON RESTULOGAM 14/1 SMA | D54: 38500 | K54: Kt.26.037 | L54: KONTRABON RESTULOGAM 14/1 SMA | M54: 38500
...

Sheet Pengan Juan Rt Bu Ani
A1: REKAPAN PENGAJUAN
A2: PER TANGGAL 14 Januari 2026
A3: POSISI KAS SAAT INI
C4: Kas Besar (Nisa) | D4: =34774000 -> 34774000
C5: Mandiri Akhmad Jaelani
C6: Mandiri CBS
C7: BJB CBS
C8: BJB CRS
C9: BRI CRS
A11: TOTAL POSISI KAS DAN BANK TGL 14 Januari 2026 | H11: =SUM(D4:D9) -> 34774000
A12: RT Bu ANI
B13: Kt.26.039 | C13: Upah Tukang RT Bu Ani | D13: 1280000
B14: Kt.26.039 | C14: Upah Pa Heri RT Bu Ani | D14: =220000*2 -> 440000
B15: Kt.26.039 | C15: Upah Pa Dedi RT Bu Ani | D15: =150000*4 -> 600000
B16: Kt.26.039 | C16: Pemb Matrial RT Bu Ani | D16: 2120000
C18: JUMLAH PENGAJUAN RT Bu Ani | D18: =SUM(D13:D17) -> 4440000
C19: Jumlah Yang Belum Dibayar | E19: =D18 -> 4440000
A20: Kontrabon
B21: Kt.26.028 | C21: KONTRABON RESTULOGAM 12/1 Rt Bu Ani | D21: 130000
C26: JUMLAH PENGAJUAN RT Bu Ani | D26: =SUM(D21:D25) -> 130000
C27: Jumlah Yang Belum Dibayar | E27: =D26 -> 130000
A28: TOTAL PENGAJUAN | E28: =E19+E27 -> 4570000
A29: TAMBAHAN PENGAJUAN
A35: JUMLAH | D35: =SUM(D30:D34) -> 0
A36: TOTAL
A38: PENCAIRAN
A39: NO | B39: TANGGAL | C39: KETERANGAN | D39: JUMLAH | E39: PARAF
C45: Jumlah Penerimaan | D45: =SUM(D40:D44) -> 0

Sheet Sheet5
A1: PA HERI | C1: Pa Dedi | E1: PA MAMAT | G1: NISA | I1: Pa Uden | K1: Pa Engkus
A2: Upah Pa Heri Pro SMP | B2: 220000 | C2: Upah Pa Dedi Ke Jakarta | D2: 270000 | E2: Upah Tukang (Pa mamat) Pek Pasang Karpet,Aksesoris,dll Pro SMP | F2: 1110000 | G2: Kerohiman (Pa Ocid) | H2: 500000 | I2: Pemb Tinta HP Smart 7740 (4 Btl) | J2: 2000000
A3: Upah Pa Heri (Sumedang) | B3: 660000 | C3: Upah Pa Dedi (5 Hari) Pro SMA | D3: 300000 | E3: Upah Tukang Pa Mamat (Pek Dren AC 201 LT 2 )Pro SMA | F3: 2480000 | G3: Pelunasan Pek Gordeng Pro SD | H3: 4068000 | I3: Buku Pengajuan | J3: 300000
A4: Kekurangan Kas Logistik | B4: 54000 | C4: Upah Pa Dedi RT Bu Ani | D4: 600000 | E4: Upah Tukang RT Bu Ani | F4: 1280000 | G4: Konsumsi Rapat 12/1 Pro SD | H4: 311500
A5: Upah Pa Heri RT Bu Ani | B5: 440000 | G5: KONTRABON RESTULOGAM 14/1 SMA | H5: 38500
G6: Pemb Matrial RT Bu Ani | H6: 2120000
G7: KONTRABON RESTULOGAM 12/1 Rt Bu Ani | H7: 130000
B15: =SUM(B2:B14) -> 1374000 | D15: =SUM(D2:D14) -> 1170000 | F15: =SUM(F2:F14) -> 4870000 | H15: =SUM(H2:H14) -> 7168000 | J15: =SUM(J2:J14) -> 2300000 | K15: =SUM(K2:K14) -> 0 | L15: =SUM(L2:L14) -> 0
C16: Kasbon | D16: 100000
F17: =F15-F4 -> 3590000
D18: =D15-D16 -> 1070000

Sheet Sheet8
A1: REKAPAN PENGAJUAN | J1: REKAPAN PENGAJUAN
A2: PER TANGGAL 22 Januari 2026 | J2: PER TANGGAL 22 Januari 2026
A3: POSISI KAS SAAT INI | J3: POSISI KAS SAAT INI
C4: Kas Besar (Nisa) | D4: 0 | L4: Kas Besar (Nisa) | M4: 0
C5: Mandiri Akhmad Jaelani | D5: 65618079 | L5: Mandiri Akhmad Jaelani | M5: 65618079
C6: Mandiri CBS (Lagi gangguan | D6: 346369459 | L6: Mandiri CBS (Lagi gangguan | M6: 346369459
C7: BJB CBS | D7: 1146153 | L7: BJB CBS | M7: 1146153
C8: BJB CRS | D8: 3297736 | L8: BJB CRS | M8: 3297736
C9: BRI CRS | D9: 2626657 | L9: BRI CRS | M9: 2626657
A11: TOTAL POSISI KAS DAN BANK TGL 22 Januari 2026 | H11: =SUM(D4:D9) -> 4.1905808e+08 | J11: TOTAL POSISI KAS DAN BANK TGL 22 Januari 2026 | Q11: =SUM(M4:M9) -> 4.1905808e+08
A12: UMUM | J12: UMUM
A13: TGL | B13: NO KAS | C13: KETERANGAN PENGAJUAN | D13: PENGAJUAN | E13: PENCAIRAN | J13: TGL | K13: NO KAS | L13: KETERANGAN PENGAJUAN | M13: PENGAJUAN | N13: PENCAIRAN
E14: SUDAH | F14: CASH | G14: GIRO | H14: TRANSFER | N14: SUDAH | O14: CASH | P14: GIRO | Q14: TRANSFER
B15: Ku.26.006 | C15: Kekurangan Pemb tinta HP Smart 7740 | D15: 500000 | K15: Ku.26.006 | L15: Kekurangan Pemb tinta HP Smart 7740 | M15: 500000
B16: Ku.26.007 | C16: Air Minum (2 Gln) | D16: 34000 | K16: Ku.26.007 | L16: Air Minum (2 Gln) | M16: 34000
B17: Ku.26.007 | C17: Aqua Gelas untuk rapat Tgl 17/1 (Talangan Pa Dedi) | D17: 30000 | K17: Ku.26.007 | L17: Aqua Gelas untuk rapat Tgl 17/1 (Talangan Pa Dedi) | M17: 30000
B18: Ku.26.007 | C18: Pemb Sapu Ijuk | D18: 50000 | K18: Ku.26.007 | L18: Pemb Sapu Ijuk | M18: 50000
C20: JUMLAH PENGAJUAN UMUM | D20: =SUM(D15:D19) -> 614000 | L20: JUMLAH PENGAJUAN UMUM | M20: =SUM(M15:M19) -> 614000
B21: Jumlah Yang Belum Dibayar | H21: =+D20 -> 614000 | K21: Jumlah Yang Belum Dibayar | Q21: =+M20 -> 614000
A22: TOTAL PENGAJUAN UMUM | E22: =+H21 -> 614000 | J22: TOTAL PENGAJUAN UMUM | N22: =+Q21 -> 614000
A23: ALCENT | J23: ALCENT
B24: Kt.26.046 | C24: Sewa Scaffolding Tgl 18/12-16/1 Pro SMA | D24: 642000 | K24: Kt.26.046 | L24: Sewa Scaffolding Tgl 18/12-16/1 Pro SMA | M24: 642000
B25: Kt.26.049 | C25: Pemb Acrilik,Wallpaper,dll Pro SMA (Pa Heri) | D25: =490000+1120000+15000 -> 1625000 | K25: Kt.26.049 | L25: Pemb Acrilik,Wallpaper,dll Pro SMA (Pa Heri)
B26: Kt.26.049 | C26: Upah Tukang Pasangan Wallppaper Pro SMA | D26: 280000 | K26: Kt.26.049 | L26: Upah Tukang Pasangan Wallppaper Pro SMA
B27: Kt.26.051 | C27: Pemb Pek Pemasangan Kawat Duri & Pengecetan (Pa Karsana) Pro SMA | D27: 2100000 | K27: Kt.26.051 | L27: Pemb Pek Pemasangan Kawat Duri & Pengecetan (Pa Karsana) Pro SMA | M27: 2100000
B28: Kt.26.055 | C28: Upah Pemasangan huruf timbul R.Tu Pro SMP (A Adit) | D28: 100000 | K28: Kt.26.055 | L28: Upah Pemasangan huruf timbul R.Tu Pro SMP (A Adit) | M28: 100000
B29: Kt.26.057 | C29: Upah Tukang (Pa Mamat) Pek Dren AC R. Yayasan,Pluran & Bocoran Pro SMA | D29: 1010000 | K29: Kt.26.057 | L29: Upah Tukang (Pa Mamat) Pek Dren AC R. Yayasan,Pluran & Bocoran Pro SMA | M29: 1010000
B30: Kt.26.057 | C30: Upah Pa Dedi Pro SMA | D30: 150000 | K30: Kt.26.057 | L30: Upah Pa Dedi Pro SMA | M30: 150000
B31: Kt.26.057 | C31: Bon matrial talangan pa Mamat (Pemb V-sock,Plug,dop,dll) Pro SMA | D31: 25000 | K31: Kt.26.057 | L31: Bon matrial talangan pa Mamat (Pemb V-sock,Plug,dop,dll) Pro SMA | M31: 25000
B32: Kt.26.057 | C32: Upah Tukang Alumunium Tgl 24 Pro SMA Bongkar Pasang Jendela | D32: 150000 | K32: Kt.26.057 | L32: Upah Tukang Alumunium Tgl 24 Pro SMA Bongkar Pasang Jendela | M32: 150000
B33: Kt.26.057 | C33: Upah Pa Heri Pro SMA | D33: 220000 | K33: Kt.26.057 | L33: Upah Pa Heri Pro SMA | M33: 220000
B34: Kt.26.058 | C34: Upah Tukang Listrik Tgl 24 (Pasang Lampu Area perpus) Pa Soni Pro TK | D34: 150000 | K34: Kt.26.058 | L34: Upah Tukang Listrik Tgl 24 (Pasang Lampu Area perpus) Pa Soni Pro TK | M34: 150000
B35: Kt.26.058 | C35: Upah Pa Heri Pro TK | D35: =220000 -> 220000 | K35: Kt.26.058 | L35: Upah Pa Heri Pro TK | M35: =220000 -> 220000
B36: Kt.26.059 | C36: Upah Pa Heri Pro SD | D36: 220000 | K36: Kt.26.059 | L36: Upah Pa Heri Pro SD | M36: 220000
B37: Kt.26.060 | C37: Pelunasan perbaikan pintu SMA (Yoda) | D37: 1000000 | K37: Kt.26.060 | L37: Pelunasan perbaikan pintu SMA (Yoda) | M37: 1000000
C39: JUMLAH PENGAJUAN SD,SMP,SMA | D39: =SUM(D24:D37) -> 7892000 | L39: JUMLAH PENGAJUAN SD,SMP,SMA | M39: =SUM(M24:M37) -> 5987000
C40: Jumlah Yang Belum Dibayar | E40: =D39 -> 7892000 | L40: Jumlah Yang Belum Dibayar | N40: =M39 -> 5987000
A41: Jl. Gitar & Antapani | J41: Jl. Gitar & Antapani
B42: Kt.26.043 | C42: Pemb Pressure Control Pro Jl Gitar | D42: 380000 | K42: Kt.26.043 | L42: Pemb Pressure Control Pro Jl Gitar | M42: 380000
B43: Kt.26.047 | C43: Sewa Scaffolding Tgl 7 Des 25 - 5 Jan 26 Jl Gitar | D43: 92500 | K43: Kt.26.047 | L43: Sewa Scaffolding Tgl 7 Des 25 - 5 Jan 26 Jl Gitar | M43: 92500
...

Sheet Pengajuan RT BU Ani 
A1: REKAPAN PENGAJUAN
A2: PER TANGGAL 22 Januari 2026
A3: POSISI KAS SAAT INI
C4: Kas Besar (Nisa) | D4: 28060000
C5: Mandiri Akhmad Jaelani
C6: Mandiri CBS
C7: BJB CBS
C8: BJB CRS
C9: BRI CRS
A11: TOTAL POSISI KAS DAN BANK TGL 22 Januari 2026 | H11: =SUM(D4:D9) -> 28060000
A12: RT Bu ANI
B13: Kt.26.039 | C13: Upah Tukang RT Bu Ani | D13: 2978000
B14: Kt.26.039 | C14: Upah Pa Heri RT Bu Ani | D14: =220000*2 -> 440000
B15: Kt.26.039 | C15: Upah Pa Dedi RT Bu Ani | D15: =150000*6 -> 900000
C18: JUMLAH PENGAJUAN RT Bu Ani | D18: =SUM(D13:D17) -> 4318000
C19: Jumlah Yang Belum Dibayar | E19: =D18 -> 4318000
A20: Kontrabon
C26: JUMLAH PENGAJUAN RT Bu Ani | D26: =SUM(D21:D25) -> 0
C27: Jumlah Yang Belum Dibayar | E27: =D26 -> 0
A28: TOTAL PENGAJUAN | E28: =E19+E27 -> 4318000
A29: TAMBAHAN PENGAJUAN
A35: JUMLAH | D35: =SUM(D30:D34) -> 0
A36: TOTAL
A38: PENCAIRAN
A39: NO | B39: TANGGAL | C39: KETERANGAN | D39: JUMLAH | E39: PARAF
C45: Jumlah Penerimaan | D45: =SUM(D40:D44) -> 0

Sheet Sheet6
A1: PA HERI | C1: Pa Dedi | E1: PA MAMAT | G1: NISA | I1: Pa Uden | K1: Pa Engkus
A2: Upah Pa Heri Pro SMP | B2: 220000 | C2: Upah Pa Dedi Ke Jakarta | D2: 270000 | E2: Upah Tukang (Pa mamat) Pek Pasang Karpet,Aksesoris,dll Pro SMP | F2: 1110000 | G2: Kerohiman (Pa Ocid) | H2: 500000 | I2: Pemb Tinta HP Smart 7740 (4 Btl) | J2: 2000000
A3: Upah Pa Heri (Sumedang) | B3: 660000 | C3: Upah Pa Dedi (5 Hari) Pro SMA | D3: 300000 | E3: Upah Tukang Pa Mamat (Pek Dren AC 201 LT 2 )Pro SMA | F3: 2480000 | G3: Pelunasan Pek Gordeng Pro SD | H3: 4068000 | I3: Buku Pengajuan | J3: 300000
A4: Kekurangan Kas Logistik | B4: 54000 | C4: Upah Pa Dedi RT Bu Ani | D4: 600000 | E4: Upah Tukang RT Bu Ani | F4: 1280000 | G4: Konsumsi Rapat 12/1 Pro SD | H4: 311500
A5: Upah Pa Heri RT Bu Ani | B5: 440000 | G5: KONTRABON RESTULOGAM 14/1 SMA | H5: 38500
G6: Pemb Matrial RT Bu Ani | H6: 2120000
G7: KONTRABON RESTULOGAM 12/1 Rt Bu Ani | H7: 130000
B15: =SUM(B2:B14) -> 1374000 | D15: =SUM(D2:D14) -> 1170000 | F15: =SUM(F2:F14) -> 4870000 | H15: =SUM(H2:H14) -> 7168000 | J15: =SUM(J2:J14) -> 2300000 | K15: =SUM(K2:K14) -> 0 | L15: =SUM(L2:L14) -> 0
C16: Kasbon | D16: 100000
F17: =F15-F4 -> 3590000
D18: =D15-D16 -> 1070000

Sheet Sheet9
A1: REKAPAN PENGAJUAN | J1: REKAPAN PENGAJUAN
A2: PER TANGGAL 29 Januari 2026 | J2: PER TANGGAL 29 Januari 2026
A3: POSISI KAS SAAT INI | J3: POSISI KAS SAAT INI
C4: Kas Besar (Nisa) | D4: 0 | L4: Kas Besar (Nisa) | M4: 0
C5: Mandiri Akhmad Jaelani | D5: 48518079 | L5: Mandiri Akhmad Jaelani | M5: 48518079
C6: Mandiri CBS | D6: 346369459 | L6: Mandiri CBS | M6: 346369459
C7: BJB CBS | D7: 1146153 | L7: BJB CBS | M7: 1146153
C8: BJB CRS | D8: 3297736 | L8: BJB CRS | M8: 3297736
C9: BRI CRS | D9: 2626657 | L9: BRI CRS | M9: 2626657
A11: TOTAL POSISI KAS DAN BANK TGL 29 Januari 2026 | H11: =SUM(D4:D9) -> 401958084 | J11: TOTAL POSISI KAS DAN BANK TGL 29 Januari 2026 | Q11: =SUM(M4:M9) -> 401958084
A12: UMUM | J12: UMUM
A13: TGL | B13: NO KAS | C13: KETERANGAN PENGAJUAN | D13: PENGAJUAN | E13: PENCAIRAN | J13: TGL | K13: NO KAS | L13: KETERANGAN PENGAJUAN | M13: PENGAJUAN | N13: PENCAIRAN
E14: SUDAH | F14: CASH | G14: GIRO | H14: TRANSFER | N14: SUDAH | O14: CASH | P14: GIRO | Q14: TRANSFER
B15: Ku.25.011 | C15: Service Motor Beat | D15: 350000 | K15: Ku.25.011 | L15: Service Motor Beat
B16: Ku.25.011 | C16: Pemb Materai | D16: 300000 | K16: Ku.25.011 | L16: Pemb Materai
B17: Ku.25.011 | C17: Upah Pa Dedi | D17: 150000 | K17: Ku.25.011 | L17: Upah Pa Dedi | M17: 150000
B18: Ku.25.011 | C18: Upah Pa Heri (Buana Sari) | D18: 440000 | K18: Ku.25.011 | L18: Upah Pa Heri (Buana Sari) | M18: 440000
B19: Ku.25.012 | C19: BPJS Kesehatan | D19: 1194312 | K19: Ku.25.012 | L19: BPJS Kesehatan
B20: Ku.25.012 | C20: BPJS Tenaga Kerja | D20: 450000 | K20: Ku.25.012 | L20: BPJS Tenaga Kerja
B21: Ku.25.012 | C21: BPJS PA Bey | D21: 202500 | K21: Ku.25.012 | L21: BPJS PA Bey
B22: Ku.25.012 | C22: Iuran rt rw | D22: 250000 | K22: Ku.25.012 | L22: Iuran rt rw
B23: Ku.25.012 | C23: Telphone & Internet | D23: 503500 | K23: Ku.25.012 | L23: Telphone & Internet
B24: Ku.25.012 | C24: Listrik | D24: 503500 | K24: Ku.25.012 | L24: Listrik
B25: Ku.25.012 | C25: Kebutuhan kantor | D25: 350000 | K25: Ku.25.012 | L25: Kebutuhan kantor | M25: 350000
B26: Ku.25.012 | C26: ATK (Pemb Map Plastik) | D26: 100000 | K26: Ku.25.012 | L26: ATK (Pemb Map Plastik)
C28: JUMLAH PENGAJUAN UMUM | D28: =SUM(D15:D27) -> 4793812 | L28: JUMLAH PENGAJUAN UMUM | M28: =SUM(M15:M27) -> 940000
B29: Jumlah Yang Belum Dibayar | H29: =+D28 -> 4793812 | K29: Jumlah Yang Belum Dibayar | Q29: =+M28 -> 940000
A30: TOTAL PENGAJUAN UMUM | E30: =+H29 -> 4793812 | J30: TOTAL PENGAJUAN UMUM | N30: =+Q29 -> 940000
A31: ALCENT | J31: ALCENT
B32: Kt.26.049 | C32: Upah Pasang Wallpaper Pro SMA | D32: 320000 | K32: Kt.26.049 | L32: Upah Pasang Wallpaper Pro SMA | M32: 320000
B33: Kt.26.074 | C33: Pemb Lampu Inlite (Talangan Pa Heri) Pro TK | D33: 83500 | K33: Kt.26.074 | L33: Pemb Lampu Inlite (Talangan Pa Heri) Pro TK | M33: 83500
B34: Kt.26.069 | C34: Buang Sampah Barangkal & BBM Pro SMP 13 | D34: 200000 | K34: Kt.26.069 | L34: Buang Sampah Barangkal & BBM Pro SMP 13 | M34: 200000
B35: Kt.26.075 | C35: Pek Pembuatan Tiang Bendera Portable (Pa Karsana) Pro SMP | D35: 1500000 | K35: Kt.26.075 | L35: Pek Pembuatan Tiang Bendera Portable (Pa Karsana) Pro SMP
B36: Kt.26.076 | C36: Pemb Matrial (Pemb Cat Dulux) Pro TK (A Adit) | D36: 1940000 | K36: Kt.26.076 | L36: Pemb Matrial (Pemb Cat Dulux) Pro TK (A Adit) | M36: 1940000
B37: Kt.26.076 | C37: Upah Tukang Pa Mamat (Pekerjaan Pegecetan Ruang Kls Pro TK/EN | D37: 320000 | K37: Kt.26.076 | L37: Upah Tukang Pa Mamat (Pekerjaan Pegecetan Ruang Kls Pro TK/EN | M37: 320000
B38: Kt.26.079 | C38: Upah Tukang Pa Mamat (Pek Perapihan R. UKS & Perapihan Bolongan Plafond) SD | D38: 360000 | K38: Kt.26.079 | L38: Upah Tukang Pa Mamat (Pek Perapihan R. UKS & Perapihan Bolongan Plafond) SD | M38: 360000
B39: Kt.26.079 | C39: Upah Pa Heri Pro SD | D39: 220000 | K39: Kt.26.079 | L39: Upah Pa Heri Pro SD | M39: 220000
B40: Kt.26.079 | C40: Upah Tukang Listrik Pro SD | D40: 150000 | K40: Kt.26.079 | L40: Upah Tukang Listrik Pro SD | M40: 150000
B41: Kt.26.080 | C41: Upah Tukang Pa Mamat (Pekerjaan Bocoran Lt. 3 ) Pro SMA | D41: 460000 | K41: Kt.26.080 | L41: Upah Tukang Pa Mamat (Pekerjaan Bocoran Lt. 3 ) Pro SMA | M41: 460000
B42: Kt.26.082 | C42: Upah Tukang Pa Mamat (Pek Pelapisan cat Plafond & Tambal solam genteng) SMP 13 | D42: 1880000 | K42: Kt.26.082 | L42: Upah Tukang Pa Mamat (Pek Pelapisan cat Plafond & Tambal solam genteng) SMP 13 | M42: 1880000
...

Sheet Pengajuan RT Bu Ani 3
A1: REKAPAN PENGAJUAN
A2: PER TANGGAL 22 Januari 2026
A3: POSISI KAS SAAT INI
C4: Kas Besar (Nisa) | D4: 28060000
C5: Mandiri Akhmad Jaelani
C6: Mandiri CBS
C7: BJB CBS
C8: BJB CRS
C9: BRI CRS
A11: TOTAL POSISI KAS DAN BANK TGL 22 Januari 2026 | H11: =SUM(D4:D9) -> 28060000
A12: RT Bu ANI
B13: Kt.26.081 | C13: Upah Tukang RT Bu Ani | D13: 3150000
B14: Kt.26.081 | C14: Upah Pa Heri RT Bu Ani | D14: =220000*3 -> 660000
B15: Kt.26.081 | C15: Upah Pa Dedi RT Bu Ani | D15: 600000
C18: JUMLAH PENGAJUAN RT Bu Ani | D18: =SUM(D13:D17) -> 4410000
C19: Jumlah Yang Belum Dibayar | E19: =D18 -> 4410000
A20: Kontrabon
C26: JUMLAH PENGAJUAN RT Bu Ani | D26: =SUM(D21:D25) -> 0
C27: Jumlah Yang Belum Dibayar | E27: =D26 -> 0
A28: TOTAL PENGAJUAN | E28: =E19+E27 -> 4410000
A29: TAMBAHAN PENGAJUAN
A35: JUMLAH | D35: =SUM(D30:D34) -> 0
A36: TOTAL
A38: PENCAIRAN
A39: NO | B39: TANGGAL | C39: KETERANGAN | D39: JUMLAH | E39: PARAF
C45: Jumlah Penerimaan | D45: =SUM(D40:D44) -> 0

Sheet Sheet11
A1: PA HERI | C1: Pa Dedi | E1: PA MAMAT | G1: NISA | I1: Pa Uden | K1: Pa Engkus
A2: Upah Pa Heri (Buana Sari) | B2: 440000 | C2: Upah Pa Dedi | D2: 150000 | E2: Upah Tukang Pa Mamat (Pekerjaan Pegecetan Ruang Kls Pro TK/EN | F2: 320000 | G2: Kebutuhan kantor | H2: 350000
A3: Upah Pasang Wallpaper Pro SMA | B3: 320000 | C3: Upah Pa Dedi Pro SMP 13 | D3: 300000 | E3: Upah Tukang Pa Mamat (Pek Perapihan R. UKS & Perapihan Bolongan Plafond) SD | F3: 360000 | G3: Buang Sampah Barangkal & BBM Pro SMP 13 | H3: 200000
A4: Pemb Lampu Inlite (Talangan Pa Heri) Pro TK | B4: 83500 | C4: Upah Pa Dedi RT Bu Ani | D4: 600000 | E4: Upah Tukang Pa Mamat (Pekerjaan Bocoran Lt. 3 ) Pro SMA | F4: 460000 | G4: Pemb Matrial (Pemb Cat Dulux) Pro TK (A Adit) | H4: 1940000
A5: Upah Pa Heri Pro SD | B5: 220000 | E5: Upah Tukang Pa Mamat (Pek Pelapisan cat Plafond & Tambal solam genteng) SMP 13 | F5: 1880000 | G5: Pek Perbaikan AC SD | H5: 1235000
A6: Upah Tukang Listrik Pro SD | B6: 150000 | G6: Service Motor Beat | H6: 350000
A7: Upah Tukang Pro Tanggerang | B7: 325000 | G7: Upah Tukang RT Bu Ani | H7: 3150000
A8: Upah Pa Heri RT Bu Ani | B8: =220000*3 -> 660000
B15: =SUM(B2:B14) -> 2198500 | D15: =SUM(D2:D14) -> 1050000 | F15: =SUM(F2:F14) -> 3020000 | H15: =SUM(H2:H14) -> 7225000 | J15: =SUM(J2:J14) -> 0 | K15: =SUM(K2:K14) -> 0 | L15: =SUM(L2:L14) -> 0
C16: Kasbon | D16: 100000
D17: =+D15-D16 -> 950000
L18: =+H15+F15+D15+B15 -> 13493500

Sheet Sheet 12
A1: REKAPAN PENGAJUAN | J1: REKAPAN PENGAJUAN
A2: PER TANGGAL 05 Februari 2026 | J2: PER TANGGAL 05 Februari 2026
A3: POSISI KAS SAAT INI | J3: POSISI KAS SAAT INI
C4: Kas Besar (Nisa) | D4: 0 | L4: Kas Besar (Nisa) | M4: 0
C5: Mandiri Akhmad Jaelani | D5: 70265 | L5: Mandiri Akhmad Jaelani | M5: 70265
C6: Mandiri CBS (Lagi gangguan | D6: 288673500 | L6: Mandiri CBS (Lagi gangguan | M6: 288673500
C7: BJB CBS | D7: 1146153 | L7: BJB CBS | M7: 1146153
C8: BJB CRS | D8: 3297736 | L8: BJB CRS | M8: 3297736
C9: BRI CRS | D9: 2626657 | L9: BRI CRS | M9: 2626657
A11: TOTAL POSISI KAS DAN BANK TGL 05 Februari 2026 | H11: =SUM(D4:D9) -> 295814311 | J11: TOTAL POSISI KAS DAN BANK TGL 05 Februari 2026 | Q11: =SUM(M4:M9) -> 295814311
A12: UMUM | J12: UMUM
A13: TGL | B13: NO KAS | C13: KETERANGAN PENGAJUAN | D13: PENGAJUAN | E13: PENCAIRAN | J13: TGL | K13: NO KAS | L13: KETERANGAN PENGAJUAN | M13: PENGAJUAN | N13: PENCAIRAN
E14: SUDAH | F14: CASH | G14: GIRO | H14: TRANSFER | N14: SUDAH | O14: CASH | P14: GIRO | Q14: TRANSFER
B15: Ku.26.011 | C15: Service Motor Beat | D15: 350000 | K15: Ku.26.011 | L15: Service Motor Beat | M15: 350000
B16: Ku.26.011 | C16: Pemb Materai | D16: 300000 | K16: Ku.26.011 | L16: Pemb Materai | M16: 300000
B17: Ku.26.011 | C17: Service Motor Jupiter | D17: 49500 | K17: Ku.26.011 | L17: Service Motor Jupiter | M17: 49500
B18: Ku.26.012 | C18: BPJS Kesehatan | D18: 1194312 | K18: Ku.26.012 | L18: BPJS Kesehatan | M18: 1194312
B19: Ku.26.012 | C19: BPJS Tenaga Kerja | D19: 450000 | K19: Ku.26.012 | L19: BPJS Tenaga Kerja | M19: 450000
B20: Ku.26.012 | C20: BPJS PA Bey | D20: 202500 | K20: Ku.26.012 | L20: BPJS PA Bey | M20: 202500
B21: Ku.26.012 | C21: Iuran rt rw | D21: 250000 | K21: Ku.26.012 | L21: Iuran rt rw | M21: 250000
B22: Ku.26.012 | C22: Telphone & Internet | D22: 503500 | K22: Ku.26.012 | L22: Telphone & Internet | M22: 503500
B23: Ku.26.012 | C23: Listrik | D23: 503500 | K23: Ku.26.012 | L23: Listrik | M23: 503500
B24: Ku.26.014 | C24: Air Minum 3 Gln | D24: 48000 | K24: Ku.26.014 | L24: Air Minum 3 Gln | M24: 48000
B25: Ku.26.014 | C25: Konsumsi Kunjungan SD White Bee Tgl 4/2 | D25: =450000+260000+26000 -> 736000 | K25: Ku.26.014 | L25: Konsumsi Kunjungan SD White Bee Tgl 4/2 | M25: =450000+260000+26000 -> 736000
C26: Pemb Brankas | D26: 1000000 | K26: Ku.26.014 | L26: Pemb Brankas | M26: 1000000
C29: JUMLAH PENGAJUAN UMUM | D29: =SUM(D15:D28) -> 5587312 | L29: JUMLAH PENGAJUAN UMUM | M29: =SUM(M15:M28) -> 5587312
B30: Jumlah Yang Belum Dibayar | H30: =+D29 -> 5587312 | K30: Jumlah Yang Belum Dibayar | Q30: =+M29 -> 5587312
A31: TOTAL PENGAJUAN UMUM | E31: =+H30 -> 5587312 | J31: TOTAL PENGAJUAN UMUM | N31: =+Q30 -> 5587312
A32: ALCENT | J32: ALCENT
B33: Kt.26.075 | C33: Pek Pembuatan Tiang Bendera Portable (Pa Karsana) Pro SMP | D33: 1500000 | K33: Kt.26.075 | L33: Pek Pembuatan Tiang Bendera Portable (Pa Karsana) Pro SMP | M33: 1500000
B34: Kt.26.094 | C34: Pek Pembuatan Rangka Meja Multimedia (Pa Karsana) Pro SMA | D34: 700000 | K34: Kt.26.094 | L34: Pek Pembuatan Rangka Meja Multimedia (Pa Karsana) Pro SMA | M34: 700000
B35: Kt.26.100 | C35: Sewa Scaffolding (Perpanjangan) Pro SMA | D35: 69000 | K35: Kt.26.100 | L35: Sewa Scaffolding (Perpanjangan) Pro SMA | M35: 69000
B36: Kt.26.101 | C36: Upah Tukang (Pengecetan Ruang Kls EN,Manhole Arba R. Guru,dll) Pro SD/TK EN | D36: 1121000 | K36: Kt.26.101 | L36: Upah Tukang (Pengecetan Ruang Kls EN,Manhole Arba R. Guru,dll) Pro SD/TK EN | M36: 1121000
B37: Kt.26.101 | C37: Upah Lemburan Tukang (Pek Pengecetan R. EN) Pro SD/TK EN | D37: 270000 | K37: Kt.26.101 | L37: Upah Lemburan Tukang (Pek Pengecetan R. EN) Pro SD/TK EN | M37: 270000
B38: Kt.26.101 | C38: Service Ganti Kaca Pro SD/TK EN | D38: 300000 | K38: Kt.26.101 | L38: Service Ganti Kaca Pro SD/TK EN | M38: 300000
B39: Kt.26.102 | C39: Upah Tukang Pa Mamat (Pek Pengecetan R. Wakasek,Pasang Lis Alumunium,dll) Pro SMP Alcent | D39: 635000 | K39: Kt.26.102 | L39: Upah Tukang Pa Mamat (Pek Pengecetan R. Wakasek,Pasang Lis Alumunium,dll) Pro SMP Alcent | M39: 635000
B40: Kt.26.102 | C40: Upah Pa Heri Pro SMP | D40: 220000 | K40: Kt.26.102 | L40: Upah Pa Heri Pro SMP | M40: 220000
B41: Kt.26.102 | C41: Upah Tukang Listrik Pa Soni (Pek Pemasngan Lampu) Pro SMP | D41: 150000 | K41: Kt.26.102 | L41: Upah Tukang Listrik Pa Soni (Pek Pemasngan Lampu) Pro SMP | M41: 150000
B42: Kt.26.103 | C42: Upah Tukang Pa Mamat (Pek Dren AC Area Sapras Lt 1,2,3,Tutup lubang Plafond,Exhaust R LSU dll) Pro SMA | D42: 880000 | K42: Kt.26.103 | L42: Upah Tukang Pa Mamat (Pek Dren AC Area Sapras Lt 1,2,3,Tutup lubang Plafond,Exhaust R LSU dll) Pro SMA | M42: 880000
B43: Kt.26.103 | C43: Pelunasan Pek Perbaikan Pintu HPL (Pa Yoda) Pro SMA | D43: 500000 | K43: Kt.26.103 | L43: Pelunasan Pek Perbaikan Pintu HPL (Pa Yoda) Pro SMA | M43: 500000
...

Sheet Pengajuan RT bu Ani ke 4
A1: REKAPAN PENGAJUAN
A2: PER TANGGAL 22 Januari 2026
A3: POSISI KAS SAAT INI
C4: Kas Besar (Nisa) | D4: 28060000
C5: Mandiri Akhmad Jaelani
C6: Mandiri CBS
C7: BJB CBS
C8: BJB CRS
C9: BRI CRS
A11: TOTAL POSISI KAS DAN BANK TGL 22 Januari 2026 | H11: =SUM(D4:D9) -> 28060000
A12: RT Bu ANI
B13: Kt.26.081 | C13: Upah Tukang RT Bu Ani | D13: 2250000
B14: Kt.26.081 | C14: Upah Pa Heri RT Bu Ani | D14: 220000
B15: Kt.26.081 | C15: Upah Pa Dedi RT Bu Ani | D15: 450000
C18: JUMLAH PENGAJUAN RT Bu Ani | D18: =SUM(D13:D17) -> 2920000
C19: Jumlah Yang Belum Dibayar | E19: =D18 -> 2920000
A20: Kontrabon
C26: JUMLAH PENGAJUAN RT Bu Ani | D26: =SUM(D21:D25) -> 0
C27: Jumlah Yang Belum Dibayar | E27: =D26 -> 0
A28: TOTAL PENGAJUAN | E28: =E19+E27 -> 2920000
A29: TAMBAHAN PENGAJUAN
A35: JUMLAH | D35: =SUM(D30:D34) -> 0
A36: TOTAL
A38: PENCAIRAN
A39: NO | B39: TANGGAL | C39: KETERANGAN | D39: JUMLAH | E39: PARAF
C45: Jumlah Penerimaan | D45: =SUM(D40:D44) -> 0

Sheet Sheet14
A1: PA HERI | C1: Pa Dedi | E1: PA MAMAT | G1: NISA | I1: Pa Uden | K1: Pa Engkus
A2: Service Ganti Kaca Pro SD/TK EN | B2: 300000 | C2: Upah Pa Dedi Pro SMP 13 | D2: 150000 | E2: Upah Tukang (Pengecetan Ruang Kls EN,Manhole Arba R. Guru,dll) Pro SD/TK EN | F2: 1121000 | G2: Service Motor Beat | H2: 350000
A3: Upah Pa Heri Pro SMP | B3: 220000 | C3: Upah Pa Dedi Pro Sumedang | D3: 150000 | E3: Upah Lemburan Tukang (Pek Pengecetan R. EN) Pro SD/TK EN | F3: 270000 | G3: Pemb Materai | H3: 300000
A4: Upah Tukang Listrik Pa Soni (Pek Pemasngan Lampu) Pro SMP | B4: 150000 | C4: Upah Pa Dedi Pro Tanggerang | D4: 450000 | E4: Upah Tukang Pa Mamat (Pek Pengecetan R. Wakasek,Pasang Lis Alumunium,dll) Pro SMP Alcent | F4: 635000
A5: Upah Pa Heri Pro SMP 13 | B5: 440000 | C5: Upah Pa Dedi RT Bu Ani | D5: 450000 | E5: Upah Tukang Pa Mamat (Pek Dren AC Area Sapras Lt 1,2,3,Tutup lubang Plafond,Exhaust R LSU dll) Pro SMA | F5: 880000 | G5: BPJS Kesehatan | H5: 1194312
A6: Bon Matrial Pa Heri (Pemb Cat) + Admin Pro SMP 13 | B6: 306500 | E6: Upah Tukang Pa Mamat (Pek Bongkaran Kusen,dempul tembok,Pengecetan tembok,dll) Pro SMP 13 | F6: 1625000 | G6: BPJS Tenaga Kerja | H6: 450000
A7: Pekerjaan Alumunium Pro SMP 13 | B7: 2000000 | G7: BPJS PA Bey | H7: 202500
A8: Upah Pa Heri Pro Sumedang | B8: 220000 | G8: Iuran rt rw | H8: 250000
A9: Upah Tukang Pro Tanggerang (Pa iyan & Pa wiwin) | B9: 1625000 | G9: Telphone & Internet | H9: 503500
A10: Upah Pa Heri RT Bu Ani | B10: 220000 | G10: Listrik | H10: 503500
A11: Service Motor Jupiter | B11: 49500 | G11: Air Minum 3 Gln | H11: 48000
G12: Konsumsi Kunjungan SD White Bee Tgl 4/2 | H12: 736000
G13: Pemb Brankas | H13: 1000000
G14: Pek Pembuatan Tiang Bendera Portable (Pa Karsana) Pro SMP | H14: 1500000
G15: Pek Pembuatan Rangka Meja Multimedia (Pa Karsana) Pro SMA | H15: 700000
G16: Sewa Scaffolding (Perpanjangan) Pro SMA | H16: 69000
G17: Pelunasan Pek Perbaikan Pintu HPL (Pa Yoda) Pro SMA | H17: 500000
G18: Sewa Scaffolding (Perpanjangan) Jl Gitar | H18: 151000
G19: KONTRABON RESTULOGAM 24/1 (Pemb Aquaproof,Kuas,Holo,dll) Pro SD | H19: 312000
G20: KONTRABON RESTULOGAM 27/1 (Pemb Aquaproof,Serat,Kuas,dll) Pro SMP 13 | H20: 1724500
G21: KONTRABON RESTULOGAM 29/1 (Pemb Skrup Gipsum) Pro SMP 13 | H21: 12000
G22: KONTRABON RESTULOGAM 3/2 (Pemb Ataboy,Lem,Amplas) Pro SMP 13 | H22: 112000
G23: KONTRABON RESTULOGAM 29/1 (Pemb Siku Alumunium,Cat,Kuas,dll) Pro SMP | H23: 215000
... G27: Upah Tukang RT Bu Ani | H27: 2250000
B29: =SUM(B2:B27) -> 5531000 | C29: =SUM(C2:C27) -> 0 | D29: =SUM(D2:D27) -> 1200000 | E29: =SUM(E2:E27) -> 0 | F29: =SUM(F2:F27) -> 4531000 | G29: =SUM(G2:G27) -> 0 | H29: =SUM(H2:H27) -> 13837812 | I29: =SUM(I2:I27) -> 0 | ... L29: =SUM(L2:L27) -> 0
C30: Kasbon | D30: 100000
C31: Kasbon dri uang (SPJ) | D31: 100000 | F31: =4550000-F29 -> 19000
L32: =H29+F29+D29+B29+A40-H27-D5-B10 -> 22179812
D33: =D29-D30-D31 -> 1000000
G37: harian Sumedang
G38: abah adoy | H38: 5 | I38: 125000 | K38: =I38*5 -> 625000
G39: iwan | H39: 5 hri | I39: 120000 | K39: =I39*5 -> 600000
G40: Aki | H40: 2 hri | I40: 130000 | K40: =I40*2 -> 260000
K42: =SUM(K38:K41)+300000 -> 1785000

Sheet Sheet 15
A1: REKAPAN PENGAJUAN | J1: REKAPAN PENGAJUAN
A2: PER TANGGAL 13 Februari 2026 | J2: PER TANGGAL 13 Februari 2026
A3: POSISI KAS SAAT INI | J3: POSISI KAS SAAT INI
C4: Kas Besar (Nisa) | D4: 390633771 | L4: Kas Besar (Nisa) | M4: 390633771
C5: Mandiri Akhmad Jaelani | D5: 62265 | L5: Mandiri Akhmad Jaelani | M5: 62265
C6: Mandiri CBS | D6: 288673500 | L6: Mandiri CBS | M6: 288673500
C7: BJB CBS | D7: 1146153 | L7: BJB CBS | M7: 1146153
C8: BJB CRS | D8: 3297736 | L8: BJB CRS | M8: 3297736
C9: BRI CRS | D9: 2626657 | L9: BRI CRS | M9: 2626657
A11: TOTAL POSISI KAS DAN BANK TGL 13 Februari 2026 | H11: =SUM(D4:D9) -> 686440082 | J11: TOTAL POSISI KAS DAN BANK TGL 13 Februari 2026 | Q11: =SUM(M4:M9) -> 686440082
A12: UMUM | J12: UMUM
A13: TGL | B13: NO KAS | C13: KETERANGAN PENGAJUAN | D13: PENGAJUAN | E13: PENCAIRAN | J13: TGL | K13: NO KAS | L13: KETERANGAN PENGAJUAN | M13: PENGAJUAN | N13: PENCAIRAN
E14: SUDAH | F14: CASH | G14: GIRO | H14: TRANSFER | N14: SUDAH | O14: CASH | P14: GIRO | Q14: TRANSFER
B15: Ku.26.017 | C15: Pemb Kertas A3 Sidu | D15: 70000 | K15: Ku.26.017 | L15: Pemb Kertas A3 Sidu | M15: 70000
B16: Ku.26.017 | C16: Kir Mobil G. Max | D16: 500000 | K16: Ku.26.017 | L16: Kir Mobil G. Max | M16: 500000
B17: Ku.26.017 | C17: Format Keuangan | D17: 1120000 | K17: Ku.26.017 | L17: Format Keuangan
B18: Ku.26.017 | C18: Service Advance | D18: 2100000 | K18: Ku.26.017 | L18: Service Advance | M18: 2100000
C29: JUMLAH PENGAJUAN UMUM | D29: =SUM(D15:D28) -> 3790000 | L29: JUMLAH PENGAJUAN UMUM | M29: =SUM(M15:M28) -> 2670000
B30: Jumlah Yang Belum Dibayar | H30: =+D29 -> 3790000 | K30: Jumlah Yang Belum Dibayar | Q30: =+M29 -> 2670000
A31: TOTAL PENGAJUAN UMUM | E31: =+H30 -> 3790000 | J31: TOTAL PENGAJUAN UMUM | N31: =+Q30 -> 2670000
A32: ALCENT | J32: ALCENT
B33: Kt.26.119 | C33: Pekerjaan Pemasangan Kanopi atap Solar Plate Pro SMA | D33: 14864000 | K33: Kt.26.119 | L33: Pekerjaan Pemasangan Kanopi atap Solar Plate Pro SMA (Pa Karsana) | M33: 14864000
B34: Kt.26.123 | C34: Kekurangan Upah tukang pasang Wallpaper Pro SMA | D34: 150000 | K34: Kt.26.123 | L34: Kekurangan Upah tukang pasang Wallpaper Pro SMA | M34: 150000
B35: Kt.26.123 | C35: Kekurangan Upah tukang Alumunium Pro SMA | D35: 360000 | K35: Kt.26.123 | L35: Kekurangan Upah tukang Alumunium Pro SMA | M35: 360000
B36: Kt.26.126 | C36: Upah Tukang Pa Mamat (Pekerjaan Perbaikan Gudang Samping 9E) Pro SMP | D36: 890000 | K36: Kt.26.126 | L36: Upah Tukang Pa Mamat (Pekerjaan Perbaikan Gudang Samping 9E) Pro SMP | M36: 890000
B37: Kt.26.127 | C37: Upah Tukang Pa Mamat (Pekrjaan Bocoran Deletasi, Area Sap,dll) Pro SMA | D37: 1130000 | K37: Kt.26.127 | L37: Upah Tukang Pa Mamat (Pekrjaan Bocoran Deletasi, Area Sap,dll) Pro SMA | M37: 1130000
C45: JUMLAH PENGAJUAN SD,SMP,SMA | D45: =SUM(D33:D44) -> 17394000 | L45: JUMLAH PENGAJUAN SD,SMP,SMA | M45: =SUM(M33:M44) -> 17394000
C46: Jumlah Yang Belum Dibayar | E46: =D45 -> 17394000 | L46: Jumlah Yang Belum Dibayar | N46: =M45 -> 17394000
A47: SMP 13 | J47: SMP 13
B48: Kt.26.128 | C48: Upah Pa Dedi Pro SMP 13 | D48: 150000 | K48: Kt.26.128 | L48: Upah Pa Dedi Pro SMP 13 | M48: 150000
C54: JUMLAH PENGAJUAN SMP 13 | D54: =SUM(D48:D52) -> 150000 | E54: 0 | F54: 0 | L54: JUMLAH PENGAJUAN SMP 13 | M54: =SUM(M48:M52) -> 150000 | N54: 0 | O54: 0
C55: Jumlah Yang Belum Dibayar | E55: =D54 -> 150000 | L55: Jumlah Yang Belum Dibayar | N55: =M54 -> 150000
A56: Jl. Gitar & Antapani | J56: Jl. Gitar & Antapani
B57: Kt.26.121 | C57: Upah Lemburan Pa Dedi Angkut Sofa Pro Antapani | D57: 84000 | K57: Kt.26.121 | L57: Upah Lemburan Pa Dedi Angkut Sofa Pro Antapani | M57: 84000
B58: Kt.26.121 | C58: Upah Lemburan Angkut Sofa Pro Antapani | D58: =72000+88000 -> 160000 | K58: Kt.26.121 | L58: Upah Lemburan Angkut Sofa Pro Antapani | M58: =72000+88000 -> 160000
C60: JUMLAH PENGAJUAN Jl. Gitar & Antapani | D60: =SUM(D57:D58) -> 244000 | E60: 0 | F60: 0 | L60: JUMLAH PENGAJUAN Jl. Gitar & Antapani | M60: =SUM(M57:M58) -> 244000 | N60: 0 | O60: 0
C61: Jumlah Yang Belum Dibayar | E61: =D60 -> 244000 | L61: Jumlah Yang Belum Dibayar | N61: =M60 -> 244000
A62: Sumedang | J62: Sumedang
B63: Kt.26.129 | C63: Upah Pa Heri Pro Sumedang | D63: 1320000 | K63: Kt.26.129 | L63: Upah Pa Heri Pro Sumedang | M63: 1320000
B64: Kt.26.129 | C64: Upah Pa Dedi Pro Sumedang | D64: 600000 | K64: Kt.26.129 | L64: Upah Pa Dedi Pro Sumedang | M64: 600000
...

Sheet Pengajuan RT bu Ani ke 5
A1: REKAPAN PENGAJUAN
A2: PER TANGGAL 13 Februari 2026
A3: POSISI KAS SAAT INI
C4: Kas Besar (Nisa) | D4: 28060000
C5: Mandiri Akhmad Jaelani
C6: Mandiri CBS
C7: BJB CBS
C8: BJB CRS
C9: BRI CRS
A11: TOTAL POSISI KAS DAN BANK TGL 22 Januari 2026 | H11: =SUM(D4:D9) -> 28060000
A12: RT Bu ANI
B13: Kt.26.081 | C13: Upah Tukang RT Bu Ani | D13: 3328000
B14: Kt.26.081 | C14: Upah Pa Dedi RT Bu Ani | D14: 300000
C18: JUMLAH PENGAJUAN RT Bu Ani | D18: =SUM(D13:D17) -> 3628000
C19: Jumlah Yang Belum Dibayar | E19: =D18 -> 3628000
A20: Kontrabon
C26: JUMLAH PENGAJUAN RT Bu Ani | D26: =SUM(D21:D25) -> 0
C27: Jumlah Yang Belum Dibayar | E27: =D26 -> 0
A28: TOTAL PENGAJUAN | E28: =E19+E27 -> 3628000
A29: TAMBAHAN PENGAJUAN
A35: JUMLAH | D35: =SUM(D30:D34) -> 0
A36: TOTAL
A38: PENCAIRAN
A39: NO | B39: TANGGAL | C39: KETERANGAN | D39: JUMLAH | E39: PARAF
C45: Jumlah Penerimaan | D45: =SUM(D40:D44) -> 0

Sheet Sheet 16
A1: PA HERI | C1: Pa Dedi | E1: PA MAMAT | G1: NISA | I1: Pa Uden | K1: Pa Engkus
A2: Kekurangan Upah tukang pasang Wallpaper Pro SMA | B2: 150000 | C2: Upah Pa Dedi Pro SMP 13 | D2: 150000 | E2: Upah Tukang Pa Mamat (Pekerjaan Perbaikan Gudang Samping 9E) Pro SMP | F2: 890000 | G2: Service Advance | H2: 2100000 | I2: Pemb Kertas A3 Sidu | J2: 70000
A3: Kekurangan Upah tukang Alumunium Pro SMA | B3: 360000 | C3: Upah Lemburan Pa Dedi Angkut Sofa Pro Antapani | D3: 84000 | E3: Upah Tukang Pa Mamat (Pekrjaan Bocoran Deletasi, Area Sap,dll) Pro SMA | F3: 1130000 | G3: Pekerjaan Pemasangan Kanopi atap Solar Plate Pro SMA (Pa Karsana) | H3: 14864000 | I3: Air Minum Pro Sumedang | J3: 24000
A4: Upah Lemburan Angkut Sofa Pro Antapani | B4: 160000 | C4: Upah Pa Dedi Pro Sumedang | D4: 600000 | E4: Upah Pro Sumedang (Pa Ali) | F4: 300000 | G4: Cash Bon Pa Agus Pro Sumedang | H4: 5000000
A5: Upah Pa Heri Pro Sumedang | B5: 1320000 | C5: Kir Mobil G. Max | D5: 500000 | G5: KONTRABON RESTULOGAM 31/1 (Pemb Aspal Cair) Pro SMA | H5: 220000
A6: Upah Tukang (Pa Iwan,Pa Aki,Bah oday) Pro Sumedang | B6: =1785000-300000 -> 1485000 | C6: Upah Pa Dedi RT Bu Ani | D6: 300000 | G6: KONTRABON RESTULOGAM 31/1 (Pemb Pisau Kramik) Pro SMA | H6: 75000
A7: Upah Tukang Pro Tanggerang (Pa iyan & Pa wiwin) | B7: 1625000 | G7: KONTRABON RESTULOGAM 3/2 (Pemb Pipa,Keni,Lem Asahi,dll) Pro SMA | H7: 736000
A8: Upah Lemburan Minggu Kemarin 2-6/2 Pro Tanggerang | B8: 450000 | G8: KONTRABON RESTULOGAM 5/2 (Pemb Triplek,Cat,Kayu,Paku,dll) Pro SMP 13 | H8: 414000
G9: KONTRABON RESTULOGAM 7/2 (Pemb Aquaproof,Paku,Trprntin,dll) Pro SMP Alcent | H9: 389900
G10: KONTRABON SEJAHTERA 7/2 (Pemb Matrial Listrik) Pro SMP Alcent | H10: 947000
G11: KONTRABON TEGUH 7/2 (Pemb Spandek,Paku Beton,Skrup) Pro SMP | H11: 317750
G12: KONTRABON Teguh 7/2 (Pemb Besi BJLS ) Pro SMP | H12: 228000
G13: Upah Tukang RT Bu Ani | H13: 3328000
B29: =SUM(B2:B27) -> 5550000 | C29: =SUM(C2:C27) -> 0 | D29: =SUM(D2:D27) -> 1634000 | E29: =SUM(E2:E27) -> 0 | F29: =SUM(F2:F27) -> 2320000 | G29: =SUM(G2:G27) -> 0 | H29: =SUM(H2:H27) -> 28619650 | I29: =SUM(I2:I27) -> 0 | ... L29: =SUM(L2:L27) -> 0 | N29: =J29+H29+F29+D29+B29-H13-D6 -> 34589650
A30: Kasbon Pa Iyan | B30: 490000 | C30: Kasbon Kantor | D30: 100000
C31: Kasbon dri uang (SPJ) | D31: 83500 | F31: =4550000-F29 -> 2230000
B32: =B29-B30 -> 5060000
D33: =D29-D30-D31 -> 1450500

Sheet Sheet17
A1: REKAPAN PENGAJUAN | J1: REKAPAN PENGAJUAN
A2: PER TANGGAL 20 Februari 2026 | J2: PER TANGGAL 20 Februari 2026
A3: POSISI KAS SAAT INI | J3: POSISI KAS SAAT INI
C4: Kas Besar (Nisa) | D4: 235143722 | L4: Kas Besar (Nisa) | M4: 235143722
C5: Mandiri Akhmad Jaelani | D5: 43630264 | L5: Mandiri Akhmad Jaelani | M5: 43630264
C6: Mandiri CBS | D6: 349127500 | L6: Mandiri CBS | M6: 349127500
C7: BJB CBS | D7: 1146153 | L7: BJB CBS | M7: 1146153
C8: BJB CRS | D8: 3297736 | L8: BJB CRS | M8: 3297736
C9: BRI CRS | D9: 2626657 | L9: BRI CRS | M9: 2626657
A11: TOTAL POSISI KAS DAN BANK TGL 20 Februari 2026 | H11: =SUM(D4:D9) -> 634972032 | J11: TOTAL POSISI KAS DAN BANK TGL 20 Februari 2026 | Q11: =SUM(M4:M9) -> 634972032
A12: UMUM | J12: UMUM
A13: TGL | B13: NO KAS | C13: KETERANGAN PENGAJUAN | D13: PENGAJUAN | E13: PENCAIRAN | J13: TGL | K13: NO KAS | L13: KETERANGAN PENGAJUAN | M13: PENGAJUAN | N13: PENCAIRAN
E14: SUDAH | F14: CASH | G14: GIRO | H14: TRANSFER | N14: SUDAH | O14: CASH | P14: GIRO | Q14: TRANSFER
C19: JUMLAH PENGAJUAN UMUM | D19: =SUM(D15:D18) -> 0 | L19: JUMLAH PENGAJUAN UMUM | M19: =SUM(M15:M18) -> 0
B20: Jumlah Yang Belum Dibayar | H20: =+D19 -> 0 | K20: Jumlah Yang Belum Dibayar | Q20: =+M19 -> 0
A21: TOTAL PENGAJUAN UMUM | E21: =+H20 -> 0 | J21: TOTAL PENGAJUAN UMUM | N21: =+Q20 -> 0
A22: ALCENT | J22: ALCENT
B23: Kt.26.126 | C23: Upah Tukang Pa Mamat (Pekerjaan Pembersihan sarang burung) Pro SMP | D23: 690000 | K23: Kt.26.126 | L23: Upah Tukang Pa Mamat (Pekerjaan Pembersihan sarang burung) Pro SMP | M23: 690000
B24: Kt.26.127 | C24: Upah Tukang Pa Mamat (Pekrjaan Perbaikan Tutup Plafond) Pro SMA | D24: 370000 | K24: Kt.26.127 | L24: Upah Tukang Pa Mamat (Pekrjaan Perbaikan Tutup Plafond) Pro SMA | M24: 370000
B25: Kt.26.128 | C25: Pekerjaaan Pembuatan Tiang Plafond (Pa Karsana) Pro SMA | D25: 800000 | K25: Kt.26.128 | L25: Pekerjaaan Pembuatan Tiang Plafond (Pa Karsana) Pro SMA | M25: 800000
C32: JUMLAH PENGAJUAN SD,SMP,SMA | D32: =SUM(D23:D31) -> 1860000 | L32: JUMLAH PENGAJUAN SD,SMP,SMA | M32: =SUM(M23:M31) -> 1860000
C33: Jumlah Yang Belum Dibayar | E33: =D32 -> 1860000 | L33: Jumlah Yang Belum Dibayar | N33: =M32 -> 1860000
A34: Budi Indah | J34: Budi Indah
B35: Kt.26.128 | C35: Upah pa Igo Pek Bocoran Budi Indah | D35: 130000 | K35: Kt.26.128 | L35: Upah pa Igo Pek Bocoran Budi Indah | M35: 130000
C41: JUMLAH PENGAJUAN Budi Indah | D41: =SUM(D35:D39) -> 130000 | E41: 0 | F41: 0 | L41: JUMLAH PENGAJUAN Budi Indah | M41: =SUM(M35:M39) -> 130000 | N41: 0 | O41: 0
C42: Jumlah Yang Belum Dibayar | E42: =D41 -> 130000 | L42: Jumlah Yang Belum Dibayar | N42: =M41 -> 130000
A43: Jl. Gitar & Antapani | J43: Jl. Gitar & Antapani
B44: Kt.26.121 | C44: Upah Pa iyan& Pa Igo Pro Antapani (Pek Buat saluaran & Ngeplur Bekas Bocoran) | D44: =165000+130000 -> 295000 | K44: Kt.26.121 | L44: Upah Pa iyan& Pa Igo Pro Antapani (Pek Buat saluaran & Ngeplur Bekas Bocoran) | M44: =165000+130000 -> 295000
C47: JUMLAH PENGAJUAN Jl. Gitar & Antapani | D47: =SUM(D44:D45) -> 295000 | E47: 0 | F47: 0 | L47: JUMLAH PENGAJUAN Jl. Gitar & Antapani | M47: =SUM(M44:M45) -> 295000 | N47: 0 | O47: 0
C48: Jumlah Yang Belum Dibayar | E48: =D47 -> 295000 | L48: Jumlah Yang Belum Dibayar | N48: =M47 -> 295000
A49: Sumedang | J49: Sumedang
B50: Kt.26.134 | C50: Pelunasan Matrial Besi 16 Pro Sumedang | D50: 12000000 | K50: Kt.26.134 | L50: Pelunasan Matrial Besi 16 Pro Sumedang | M50: 12000000
B51: Kt.26.149 | C51: Upah Pa Heri Pro Sumedang | D51: =220000*7 -> 1540000 | K51: Kt.26.149 | L51: Upah Pa Heri Pro Sumedang | M51: =220000*7 -> 1540000
B52: Kt.26.149 | C52: Upah Pa Dedi Pro Sumedang | D52: =150000*5 -> 750000 | K52: Kt.26.149 | L52: Upah Pa Dedi Pro Sumedang | M52: =150000*5 -> 750000
B53: Kt.26.149 | C53: Cash Bon Pa Agus Pro Sumedang | D53: 12000000 | K53: Kt.26.149 | L53: Cash Bon Pa Agus Pro Sumedang | M53: 12000000
B54: Kt.26.149 | C54: Upah Tukang (7 Orang ) Pro Sumedang | D54: 5950000 | K54: Kt.26.149 | L54: Upah Tukang (7 Orang ) Pro Sumedang | M54: 5950000
B55: Kt.26.149 | C55: Keamanan Satpam Pro Sumedang | D55: 300000 | K55: Kt.26.149 | L55: Keamanan Satpam Pro Sumedang | M55: 300000
C57: JUMLAH PENGAJUAN Sumedang | D57: =SUM(D50:D55) -> 32540000 | E57: 0 | F57: 0 | L57: JUMLAH PENGAJUAN Sumedang | M57: =SUM(M50:M55) -> 32540000 | N57: 0 | O57: 0
C58: Jumlah Yang Belum Dibayar | E58: =D57 -> 32540000 | L58: Jumlah Yang Belum Dibayar | N58: =M57 -> 32540000
A59: Tanggerang | J59: Tanggerang
...

Sheet Pengajuan Ke 6 
A1: REKAPAN PENGAJUAN
A2: PER TANGGAL 13 Februari 2026
A3: POSISI KAS SAAT INI
C4: Kas Besar (Nisa) | D4: 0
C5: Mandiri Akhmad Jaelani
C6: Mandiri CBS
C7: BJB CBS
C8: BJB CRS
C9: BRI CRS
A11: TOTAL POSISI KAS DAN BANK TGL 22 Januari 2026 | H11: =SUM(D4:D9) -> 0
A12: RT Bu ANI
B13: Kt.26.081 | C13: Upah Tukang RT Bu Ani
B14: Kt.26.081 | C14: Upah Pa Dedi RT Bu Ani | D14: 150000
C18: JUMLAH PENGAJUAN RT Bu Ani | D18: =SUM(D13:D17) -> 150000
C19: Jumlah Yang Belum Dibayar | E19: =D18 -> 150000
A20: Kontrabon
C26: JUMLAH PENGAJUAN RT Bu Ani | D26: =SUM(D21:D25) -> 0
C27: Jumlah Yang Belum Dibayar | E27: =D26 -> 0
A28: TOTAL PENGAJUAN | E28: =E19+E27 -> 150000
A29: TAMBAHAN PENGAJUAN
A35: JUMLAH | D35: =SUM(D30:D34) -> 0
A36: TOTAL
A38: PENCAIRAN
A39: NO | B39: TANGGAL | C39: KETERANGAN | D39: JUMLAH | E39: PARAF
C45: Jumlah Penerimaan | D45: =SUM(D40:D44) -> 0

Sheet Sheet19
A1: PA HERI | C1: Pa Dedi | E1: PA MAMAT | G1: NISA | I1: Pa Uden | K1: Pa Engkus
A2: Upah pa Igo Pek Bocoran Budi Indah | B2: 130000 | C2: Upah Pa Dedi Pro Sumedang | D2: 750000 | E2: Upah Tukang Pa Mamat (Pekerjaan Pembersihan sarang burung) Pro SMP | F2: 690000 | G2: Pekerjaaan Pembuatan Tiang Plafond (Pa Karsana) Pro SMA | H2: 800000
A3: Upah Pa iyan& Pa Igo Pro Antapani (Pek Buat saluaran & Ngeplur Bekas Bocoran) | B3: 295000 | C3: Upah Pa dedi Pro Tanggerang | D3: 150000 | E3: Upah Tukang Pa Mamat (Pekrjaan Perbaikan Tutup Plafond) Pro SMA | F3: 370000 | G3: Pelunasan Matrial Besi 16 Pro Sumedang | H3: 12000000
A4: Upah Pa Heri Pro Sumedang | B4: 1540000 | C4: Parkir | D4: 5000 | G4: KONTRABON RESTULOGAM 11/2 (pemb Paku,Kawat,benang) Pro Sumedang | H4: 2465000
A5: Kekuranan Kas Logistik | B5: 148000 | C5: RT Bu Ani | D5: 150000 | G5: KONTRBAON RESUOGAM 12/2 (Pemb Soket,seal Tape,Ram,dll) Pro SMA | H5: 363500
A6: Upah Tukang (7 Orang ) Pro Sumedang | B6: 5950000 | G6: KONTRABON SEJAHTERA 18/2 (Pemb Matrial Listrik) Pro Sumedang | H6: 1033000
A7: Keamanan Satpam Pro Sumedang | B7: 300000 | G7: Cash Bon Pa Agus Pro Sumedang | H7: 12000000
B29: =SUM(B2:B27) -> 8363000 | C29: =SUM(C2:C27) -> 0 | D29: =SUM(D2:D27) -> 1055000 | E29: =SUM(E2:E27) -> 0 | F29: =SUM(F2:F27) -> 1060000 | G29: =SUM(G2:G27) -> 0 | H29: =SUM(H2:H27) -> 28661500 | I29: =SUM(I2:I27) -> 0 | ... L29: =SUM(L2:L27) -> 0 | N29: =SUM(B29:M29)-150000 -> 38989500
C30: Kasbon Kantor | D30: 100000 | N30: =N29-Sheet17!M97 -> 0
D32: =D29-D30 -> 955000
B39: =10454000+1600000 -> 12054000
C40: H-beam | D40: 8 btg | E40: 21700000 | F40: =E40*8 -> 173600000
C41: Plat | D41: 2 lnr | E41: 6300000 | F41: =E41*2 -> 12600000
E43: Tambahan | F43: 15000000
F44: =F40+F41 -> 186200000

Sheet Sheet1
A1: REKAPAN PENGAJUAN | J1: REKAPAN PENGAJUAN
A2: PER TANGGAL 27 Februari 2026 | J2: PER TANGGAL 27 Februari 2026
A3: POSISI KAS SAAT INI | J3: POSISI KAS SAAT INI
C4: Kas Besar (Nisa) | D4: 8470023 | L4: Kas Besar (Nisa) | M4: 8470023
C5: Mandiri Akhmad Jaelani | D5: 1080265 | L5: Mandiri Akhmad Jaelani | M5: 1080265
C6: Mandiri CBS | D6: 1127500 | L6: Mandiri CBS | M6: 1127500
C7: BJB CBS | D7: 1146153 | L7: BJB CBS | M7: 1146153
C8: BJB CRS | D8: 3297736 | L8: BJB CRS | M8: 3297736
C9: BRI CRS | D9: 2626657 | L9: BRI CRS | M9: 2626657
A11: TOTAL POSISI KAS DAN BANK TGL 27 Februari 2026 | H11: =SUM(D4:D9) -> 17748334 | J11: TOTAL POSISI KAS DAN BANK TGL 27 Februari 2026 | Q11: =SUM(M4:M9) -> 17748334
A12: UMUM | J12: UMUM
A13: TGL | B13: NO KAS | C13: KETERANGAN PENGAJUAN | D13: PENGAJUAN | E13: PENCAIRAN | J13: TGL | K13: NO KAS | L13: KETERANGAN PENGAJUAN | M13: PENGAJUAN | N13: PENCAIRAN
E14: SUDAH | F14: CASH | G14: GIRO | H14: TRANSFER | N14: SUDAH | O14: CASH | P14: GIRO | Q14: TRANSFER
B15: Ku.26.028 | C15: BPJS Kesehatan | D15: 1194312 | K15: Ku.26.028 | L15: BPJS Kesehatan | M15: 1194312
B16: Ku.26.028 | C16: BPJS TK | D16: 450000 | K16: Ku.26.028 | L16: BPJS TK | M16: 450000
B17: Ku.26.028 | C17: BPJS Pa Bey | D17: 200000 | K17: Ku.26.028 | L17: BPJS Pa Bey | M17: 200000
B18: Ku.26.028 | C18: Telphone & Internet | D18: 503500 | K18: Ku.26.028 | L18: Telphone & Internet
B19: Ku.26.028 | C19: Listrik | D19: 503500 | K19: Ku.26.028 | L19: Listrik
C22: JUMLAH PENGAJUAN UMUM | D22: =SUM(D15:D21) -> 2851312 | L22: JUMLAH PENGAJUAN UMUM | M22: =SUM(M15:M21) -> 1844312
C23: Jumlah Yang Belum Dibayar | H23: =+D22 -> 2851312 | L23: Jumlah Yang Belum Dibayar | Q23: =+M22 -> 1844312
A24: TOTAL PENGAJUAN UMUM | E24: =+H23 -> 2851312 | J24: TOTAL PENGAJUAN UMUM | N24: =+Q23 -> 1844312
A25: ALCENT | J25: ALCENT
B26: Kt.26.176 | C26: Upah Tukang Pa Mamat (Pekerjaan Retakan Dinding R. kls, Stopkontak Lampu) Pro SD | D26: 390000 | K26: Kt.26.176 | L26: Upah Tukang Pa Mamat (Pekerjaan Retakan Dinding R. kls, Stopkontak Lampu) Pro SD | M26: 390000
B27: Kt.26.177 | C27: Upah Tukang Pa Mamat (Pek. Silent Bocoran Kusen Jendela) Pro SMA | D27: 570000 | K27: Kt.26.177 | L27: Upah Tukang Pa Mamat (Pek. Silent Bocoran Kusen Jendela) Pro SMA | M27: 570000
B28: Kt.26.169 | C28: Pekerjaan Pengaman Lampu Sorot (Pa Karsana) Pro SMA | D28: 2400000 | K28: Kt.26.169 | L28: Pekerjaan Pengaman Lampu Sorot (Pa Karsana) Pro SMA | M28: 2400000
C30: JUMLAH PENGAJUAN SD,SMP,SMA | D30: =SUM(D26:D28) -> 3360000 | L30: JUMLAH PENGAJUAN SD,SMP,SMA | M30: =SUM(M26:M28) -> 3360000
C31: Jumlah Yang Belum Dibayar | E31: =D30 -> 3360000 | L31: Jumlah Yang Belum Dibayar | N31: =M30 -> 3360000
A32: Budi Indah & Darul Ulum | J32: Budi Indah & Darul Ulum
B33: Kt.26.128 | C33: Upah Pa Dedi Budi Indah | D33: 150000 | K33: Kt.26.174 | L33: Upah Pa Dedi Budi Indah | M33: 150000
B34: Kt.26.178 | C34: Pemb Matrial (Samflex,Cornice,dll) Pro Darul Ulum | D34: 125000 | K34: Kt.26.178 | L34: Pemb Matrial (Samflex,Cornice,dll) Pro Darul Ulum | M34: 125000
C39: JUMLAH PENGAJUAN Budi Indah | D39: =SUM(D33:D37) -> 275000 | E39: 0 | F39: 0 | L39: JUMLAH PENGAJUAN Budi Indah | M39: =SUM(M33:M37) -> 275000 | N39: 0 | O39: 0
C40: Jumlah Yang Belum Dibayar | E40: =D39 -> 275000 | L40: Jumlah Yang Belum Dibayar | N40: =M39 -> 275000
A41: UPI | J41: UPI
B42: Kn.26.006 | C42: BBM Antar Berkas Tgl 20/2 & Tgl 23/2 | D42: 45000 | K42: Kn.26.006 | L42: BBM Antar Berkas Tgl 20/2 & Tgl 23/2 | M42: 45000
C45: JUMLAH PENGAJUAN UPI | D45: =SUM(D42:D43) -> 45000 | E45: 0 | F45: 0 | L45: JUMLAH PENGAJUAN UPI | M45: =SUM(M42:M43) -> 45000 | N45: 0 | O45: 0
C46: Jumlah Yang Belum Dibayar | E46: =D45 -> 45000 | L46: Jumlah Yang Belum Dibayar | N46: =M45 -> 45000
A47: Sumedang | J47: Sumedang
B48: Kt.26.175 | C48: Upah Borongan (Pa Agus) Pro Sumedang | D48: 21000000 | K48: Kt.26.175 | L48: Upah Borongan (Pa Agus) Pro Sumedang | M48: 21000000
B49: Kt.26.175 | C49: Upah Tukang (5 Org) Pro Sumedang | D49: 2700000 | K49: Kt.26.175 | L49: Upah Tukang (5 Org) Pro Sumedang | M49: 2700000
B50: Kt.26.175 | C50: Upah Heri Pro Sumedang | D50: 1540000 | K50: Kt.26.175 | L50: Upah Heri Pro Sumedang | M50: 1540000
...

Sheet Pengauan Ke 7 RT BU Ani 
A1: REKAPAN PENGAJUAN
A2: PER TANGGAL 13 Februari 2026
A3: POSISI KAS SAAT INI
C4: Kas Besar (Nisa) | D4: 0
C5: Mandiri Akhmad Jaelani
C6: Mandiri CBS
C7: BJB CBS
C8: BJB CRS
C9: BRI CRS
A11: TOTAL POSISI KAS DAN BANK TGL 22 Januari 2026 | H11: =SUM(D4:D9) -> 0
A12: RT Bu ANI
B13: Kt.26.180 | C13: Upah Tukang RT Bu Ani Minggu Lalu | D13: 1356000 | E13: 1200000 | F13: =D13-E13 -> 156000 | I13: =D13+D14-12000-6000 -> 4500000
B14: Kt.26.180 | C14: Upah Tukang RT Bu Ani Minggu ini | D14: 3162000 | E14: 450000 | F14: =D14-E14 -> 2712000
B15: Kt.26.179 | C15: Pemb Kawat Beton | D15: 25000
C18: JUMLAH PENGAJUAN RT Bu Ani | D18: =SUM(D13:D17) -> 4543000 | E18: =SUM(E13:E17) -> 1650000 | F18: =SUM(F13:F17) -> 2868000
C19: Jumlah Yang Belum Dibayar | E19: =D18 -> 4543000
A20: Kontrabon
C26: JUMLAH PENGAJUAN RT Bu Ani | D26: =SUM(D21:D25) -> 0
C27: Jumlah Yang Belum Dibayar | E27: =D26 -> 0
A28: TOTAL PENGAJUAN | E28: =E19+E27 -> 4543000
A29: TAMBAHAN PENGAJUAN
A35: JUMLAH | D35: =SUM(D30:D34) -> 0
A36: TOTAL
A38: PENCAIRAN
A39: NO | B39: TANGGAL | C39: KETERANGAN | D39: JUMLAH | E39: PARAF
C45: Jumlah Penerimaan | D45: =SUM(D40:D44) -> 0

Sheet Sheet4
A1: PA HERI | C1: Pa Dedi | E1: PA MAMAT | G1: NISA | I1: Pa Uden
A2: Pemb Matrial (Samflex,Cornice,dll) Pro Darul Ulum | B2: 125000 | C2: Upah Pa Dedi Budi Indah | D2: 150000 | E2: Upah Tukang Pa Mamat (Pekerjaan Retakan Dinding R. kls, Stopkontak Lampu) Pro SD | F2: 390000 | G2: BPJS Kesehatan | H2: 1194312
A3: Upah Tukang (5 Org) Pro Sumedang | B3: 2700000 | C3: Upah Pa Dedi Pro Sumedang | D3: 900000 | E3: Upah Tukang Pa Mamat (Pek. Silent Bocoran Kusen Jendela) Pro SMA | F3: 570000 | G3: BPJS TK | H3: 450000
A4: Upah Heri Pro Sumedang | B4: 1540000 | G4: BPJS Pa Bey | H4: 200000
A5: Keamanan Satpam Pro Sumedang | B5: 300000 | G5: Pekerjaan Pengaman Lampu Sorot (Pa Karsana) Pro SMA | H5: 2400000
G6: BBM Antar Berkas Tgl 20/2 & Tgl 23/2 | H6: 45000
G7: Upah Borongan (Pa Agus) Pro Sumedang | H7: 21000000
G8: Dp Pekerjaan Lemari Bawah Tangga (Pa Kiki) SD | H8: 3000000
B29: =SUM(B2:B27) -> 4665000 | C29: =SUM(C2:C27) -> 0 | D29: =SUM(D2:D27) -> 1050000 | E29: =SUM(E2:E27) -> 0 | F29: =SUM(F2:F27) -> 960000 | G29: =SUM(G2:G27) -> 0 | H29: =SUM(H2:H27) -> 28289312 | I29: =SUM(I2:I27) -> 0 | J29: =SUM(J2:J27) -> 0 | L29: =SUM(B29:K29) -> 34964312
C30: Kasbon Kantor | D30: 100000 | L30: =L29-Sheet1!N85 -> 0
C31: Kasbon Bu Nisa | D31: 50000
D32: =D29-D30-D31 -> 900000

Sheet Sheet3
A1: REKAPAN PENGAJUAN | J1: REKAPAN PENGAJUAN
A2: PER TANGGAL 6 Maret 2026 | J2: PER TANGGAL 6 Maret 2026
A3: POSISI KAS SAAT INI | J3: POSISI KAS SAAT INI
C4: Kas Besar (Nisa) | D4: 207524511 | L4: Kas Besar (Nisa) | M4: 207524511
C5: Mandiri Akhmad Jaelani | D5: 440765 | L5: Mandiri Akhmad Jaelani | M5: 440765
C6: Mandiri CBS | D6: 1213200 | L6: Mandiri CBS | M6: 1213200
C7: BJB CBS | D7: 1146153 | L7: BJB CBS | M7: 1146153
C8: BJB CRS | D8: 3297736 | L8: BJB CRS | M8: 3297736
C9: BRI CRS | D9: 2626657 | L9: BRI CRS | M9: 2626657
A11: TOTAL POSISI KAS DAN BANK TGL 6 Maret 2026 | H11: =SUM(D4:D9) -> 216249022 | J11: TOTAL POSISI KAS DAN BANK TGL 6 Maret 2026 | Q11: =SUM(M4:M9) -> 216249022
A12: UMUM | J12: UMUM
A13: TGL | B13: NO KAS | C13: KETERANGAN PENGAJUAN | D13: PENGAJUAN | E13: PENCAIRAN | J13: TGL | K13: NO KAS | L13: KETERANGAN PENGAJUAN | M13: PENGAJUAN | N13: PENCAIRAN
E14: SUDAH | F14: CASH | G14: GIRO | H14: TRANSFER | N14: SUDAH | O14: CASH | P14: GIRO | Q14: TRANSFER
B15: Ku.25.247 | C15: Biaya Perbaikan CCTV Kantor | D15: 4745000 | K15: Ku.25.247 | L15: Biaya Perbaikan CCTV Kantor | M15: 4745000
B16: Ku.26.028 | C16: Telphone & Internet | D16: 503500 | K16: Ku.26.028 | L16: Telphone & Internet | M16: 503500
B17: Ku.26.028 | C17: Listrik | D17: 503500 | K17: Ku.26.028 | L17: Listrik | M17: 503500
B18: Ku.26.028 | C18: Air Minum 1 Gln (Talangan Pa Uden) | D18: 16000 | K18: Ku.26.028 | L18: Air Minum 1 Gln (Talangan Pa Uden) | M18: 16000
B19: Ku.26.028 | C19: Iuran RT (Per 10 Bulan) | D19: =65000*10 -> 650000 | K19: Ku.26.028 | L19: Iuran RT (Per 10 Bulan) | M19: =65000*10 -> 650000
B20: Ku.26.028 | C20: Sumbangan Thr Rt | D20: 250000 | K20: Ku.26.028 | L20: Sumbangan Thr Rt | M20: 250000
B21: Ku.26.028 | C21: Iuran Rw | D21: 185000 | K21: Ku.26.028 | L21: Iuran Rw | M21: 185000
B22: Ku.26.028 | C22: Sumbangan Thr Rw | D22: 250000 | K22: Ku.26.028 | L22: Sumbangan Thr Rw | M22: 250000
